<?xml version="1.0" ?>
<!-- =================================================================================== -->
<!-- |    This document was autogenerated by xacro from xacro/robot_cargo_out.xacro    | -->
<!-- |    EDITING THIS FILE BY HAND IS NOT RECOMMENDED                                 | -->
<!-- =================================================================================== -->
<!-- d1cargo "out" (<>) variant: original robot.xacro is kept untouched.
     Matches urdf/robot_cargo_out.urdf and mujoco/robot_cargo_out.xml:
       - central mower payload (mesh mower.STL, 22.872 kg), lowered 2cm (mower_joint z=-0.02)
       - modules moved apart: +-0.1875 -> +-0.553 (widened +16cm/side to seat mower docking)
       - F module yawed 180deg (yaw=3.14159) -> hips inboard at +-0.4585,
         knees point outward = "<>" stance; R module not rotated
     Uses single_robot_out.xacro (yaw param + pi-compensated funtion/docking). -->
<robot name="d1cargo_description">
  <material name="black">
    <color rgba="0.19607843137254902 0.19607843137254902 0.19607843137254902 1.0"/>
  </material>
  <material name="blue">
    <color rgba="0.0 0.0 0.8 1.0"/>
  </material>
  <material name="green">
    <color rgba="0.0 0.8 0.0 1.0"/>
  </material>
  <material name="grey">
    <color rgba="0.2 0.2 0.2 1.0"/>
  </material>
  <material name="silver">
    <color rgba="0.9137254901960784 0.9137254901960784 0.8470588235294118 1.0"/>
  </material>
  <material name="orange">
    <color rgba="1.0 0.4235294117647059 0.0392156862745098 1.0"/>
  </material>
  <material name="brown">
    <color rgba="0.8705882352941177 0.8117647058823529 0.7647058823529411 1.0"/>
  </material>
  <material name="red">
    <color rgba="0.8 0.0 0.0 1.0"/>
  </material>
  <material name="white">
    <color rgba="1.0 1.0 1.0 1.0"/>
  </material>
  <link name="base_link">
    <visual>
      <origin rpy="0 0 0" xyz="0 0 0"/>
      <geometry>
        <box size="0.001 0.001 0.001"/>
      </geometry>
    </visual>
    <inertial>
      <mass value="0.001"/>
      <origin rpy="0 0 0" xyz="0 0 0"/>
      <inertia ixx="0.0001" ixy="0" ixz="0" iyy="0.0001" iyz="0" izz="0.0001"/>
    </inertial>
  </link>
  <!-- central mower payload between the two modules (SolidWorks 负载框-割草机版, 22.872 kg).
       mesh frame == base_link frame, so the fixed joint stays at the origin. -->
  <link name="mower">
    <visual>
      <origin rpy="0 0 0" xyz="0 0 0"/>
      <geometry>
        <mesh filename="package://d1_description/meshes/mower.STL"/>
      </geometry>
      <material name="">
        <color rgba="0.75294 0.75294 0.75294 1"/>
      </material>
    </visual>
    <collision>
      <origin rpy="0 0 0" xyz="0 0 0"/>
      <geometry>
        <mesh filename="package://d1_description/meshes/mower.STL"/>
      </geometry>
    </collision>
    <inertial>
      <mass value="22.872"/>
      <origin rpy="0 0 0" xyz="-0.0099654 -0.00019956 0.0801"/>
      <inertia ixx="0.59821" ixy="0.0059593" ixz="-0.0049803" iyy="1.2381" iyz="3.5606e-05" izz="1.1939"/>
    </inertial>
  </link>
  <joint name="mower_joint" type="fixed">
    <origin rpy="0 0 0" xyz="0 0 -0.02"/>
    <parent link="base_link"/>
    <child link="mower"/>
  </joint>
  <link name="imu_link">
    <inertial>
      <mass value="0.001"/>
      <origin rpy="0 0 0" xyz="0 0 0"/>
      <inertia ixx="0.0001" ixy="0" ixz="0" iyy="0.0001" iyz="0" izz="0.0001"/>
    </inertial>
    <visual>
      <origin rpy="0 0 0" xyz="0 0 0"/>
      <geometry>
        <box size="0.001 0.001 0.001"/>
      </geometry>
      <material name="red"/>
    </visual>
    <collision>
      <origin rpy="0 0 0" xyz="0 0 0"/>
      <geometry>
        <box size=".001 .001 .001"/>
      </geometry>
    </collision>
  </link>
  <joint name="imu_joint" type="fixed">
    <parent link="base_link"/>
    <child link="imu_link"/>
    <origin rpy="0 0 0" xyz="0 0 0"/>
  </joint>
  <!-- Base link -->
  <link name="F_base_link">
    <inertial>
      <origin rpy="0 0 0" xyz="0.03074 0.00016 -0.03314"/>
      <mass value="9.158"/>
      <inertia ixx="0.073416" ixy="0.00014675" ixz="-0.0079314" iyy="0.12672" iyz="1.9414e-05" izz="0.11933"/>
    </inertial>
    <visual>
      <origin rpy="0 0 0" xyz="0 0 0"/>
      <geometry>
        <mesh filename="package://d1h_description/meshes/base_link.STL"/>
      </geometry>
      <material name="">
        <color rgba="0.75294 0.75294 0.75294 1"/>
      </material>
    </visual>
    <collision>
      <origin rpy="0 0 0" xyz="0 0 0"/>
      <geometry>
        <box size="0.275 0.15 0.18"/>
      </geometry>
    </collision>
    <collision>
      <origin rpy="0 0 0" xyz="0 0 -0.12"/>
      <geometry>
        <box size="0.35 0.15 0.1"/>
      </geometry>
    </collision>
  </link>
  <joint name="F_base_joint" type="fixed">
    <origin rpy="0 0 3.14159" xyz="0.553 0 0"/>
    <parent link="base_link"/>
    <child link="F_base_link"/>
  </joint>
  <!-- Funtion link -->
  <link name="F_funtion_link">
    <inertial>
      <origin rpy="0 0 0" xyz="-0.02031 -0.00001 0.00546"/>
      <mass value="0.7859"/>
      <inertia ixx="0.005595" ixy="0.0" ixz="-4.5e-05" iyy="0.002202" iyz="0.0" izz="0.003725"/>
    </inertial>
    <visual>
      <origin rpy="0 0 0" xyz="0 0 0"/>
      <geometry>
        <mesh filename="package://d1h_description/meshes/funtion_Link.STL"/>
      </geometry>
      <material name="">
        <color rgba="0.75294 0.75294 0.75294 1"/>
      </material>
    </visual>
    <collision>
      <origin rpy="0 0 0" xyz="0.008 0 0"/>
      <geometry>
        <box size="0.0495 0.15 0.18"/>
      </geometry>
    </collision>
  </link>
  <joint name="F_funtion_joint" type="fixed">
    <origin rpy="0 0 3.14159" xyz="-0.1545 0 0"/>
    <parent link="F_base_link"/>
    <child link="F_funtion_link"/>
    <axis xyz="0 0 0"/>
  </joint>
  <!-- Docking link -->
  <link name="F_docking_link">
    <inertial>
      <origin rpy="0 0 0" xyz="0.01167 0.01142 0.00562"/>
      <mass value="1.1043"/>
      <inertia ixx="0.007968" ixy="0.000348" ixz="1.4e-05" iyy="0.002634" iyz="-1.7e-05" izz="0.005995"/>
    </inertial>
    <visual>
      <origin rpy="0 0 0" xyz="0 0 0"/>
      <geometry>
        <mesh filename="package://d1h_description/meshes/docking_Link.STL"/>
      </geometry>
      <material name="">
        <color rgba="0.75294 0.75294 0.75294 1"/>
      </material>
    </visual>
    <collision>
      <origin rpy="0 0 0" xyz="0.0065 0 0"/>
      <geometry>
        <box size="0.0495 0.15 0.175"/>
      </geometry>
    </collision>
  </link>
  <joint name="F_docking_joint" type="fixed">
    <origin rpy="0 0 3.14159" xyz="0.187 0 0"/>
    <parent link="F_base_link"/>
    <child link="F_docking_link"/>
    <axis xyz="0 0 0"/>
  </joint>
  <!-- Left hip link -->
  <link name="FL_hip">
    <inertial>
      <origin rpy="0 0 0" xyz="-0.01567766 -0.00005214 -0.09306106"/>
      <mass value="1.86700"/>
      <inertia ixx="0.004561" ixy="-0.00000066" ixz="-0.00004876" iyy="0.0034067" iyz="-0.00000146" izz="0.0026097"/>
    </inertial>
    <visual>
      <origin rpy="0 0 0" xyz="0 0 0"/>
      <geometry>
        <mesh filename="package://d1h_description/meshes/L_hip.STL"/>
      </geometry>
      <material name="">
        <color rgba="0.75294 0.75294 0.75294 1"/>
      </material>
    </visual>
  </link>
  <joint name="FL_hip_joint" type="revolute">
    <origin rpy="1.5708 0 1.5708" xyz="0.0945 0.0775 0"/>
    <parent link="F_base_link"/>
    <child link="FL_hip"/>
    <axis xyz="0 0 1"/>
    <dynamics damping="0.2346" friction="0.943"/>
    <limit effort="80" lower="-0.7853981633974483" upper="0.7853981633974483" velocity="20"/>
  </joint>
  <!-- Left thigh link -->
  <link name="FL_thigh">
    <inertial>
      <origin rpy="0 0 0" xyz="0.03137855 0.00371524 0.06475758"/>
      <mass value="2.81160"/>
      <inertia ixx="0.00486852" ixy="-0.00149035" ixz="-0.00234028" iyy="0.0203762" iyz="-0.00032034" izz="0.02095408"/>
    </inertial>
    <visual>
      <origin rpy="0 0 0" xyz="0 0 0"/>
      <geometry>
        <mesh filename="package://d1h_description/meshes/L_thigh.STL"/>
      </geometry>
      <material name="">
        <color rgba="0.75294 0.75294 0.75294 1"/>
      </material>
    </visual>
    <collision>
      <origin rpy="0 0 0.2617993877991494" xyz="0.06 0.02 0"/>
      <geometry>
        <box size="0.3 0.09 0.05"/>
      </geometry>
    </collision>
  </link>
  <joint name="FL_thigh_joint" type="revolute">
    <origin rpy="-1.5708 0 -1.5704" xyz="0.0905 0 -0.0945"/>
    <parent link="FL_hip"/>
    <child link="FL_thigh"/>
    <axis xyz="0 0 1"/>
    <dynamics damping="0.2346" friction="0.943"/>
    <limit effort="80" lower="-1.8325957145940461" upper="3.4033920413889422" velocity="20"/>
  </joint>
  <!-- Left knee link -->
  <link name="FL_calf">
    <inertial>
      <origin rpy="0 0 0" xyz="0.12683437 0.01137531 0.00486771"/>
      <mass value="0.61004"/>
      <inertia ixx="0.00034763" ixy="0.00045139" ixz="-0.00028304" iyy="0.0068336" iyz="0.00001004" izz="0.00692927"/>
    </inertial>
    <visual>
      <origin rpy="0 0 0" xyz="0 0 0"/>
      <geometry>
        <mesh filename="package://d1h_description/meshes/L_calf.STL"/>
      </geometry>
      <material name="">
        <color rgba="0.75294 0.75294 0.75294 1"/>
      </material>
    </visual>
    <collision>
      <origin rpy="0 0 -0.08" xyz="0.15 0.01 0"/>
      <geometry>
        <box size="0.3 0.04 0.05"/>
      </geometry>
    </collision>
  </link>
  <joint name="FL_calf_joint" type="revolute">
    <origin rpy="-0.0 0.0 0.0" xyz="0.25 0 0"/>
    <parent link="FL_thigh"/>
    <child link="FL_calf"/>
    <axis xyz="0 0 1"/>
    <dynamics damping="0.2346" friction="0.943"/>
    <limit effort="80" lower="-2.72" upper="-0.85" velocity="20"/>
  </joint>
  <!-- Left wheel link -->
  <link name="FL_foot">
    <inertial>
      <origin rpy="0 0 0" xyz="-0.00001088 0.00000319 0.02475"/>
      <mass value="1.75470"/>
      <inertia ixx="0.00414743" ixy="-0.00000091" ixz="0.00000144" iyy="0.00415057" iyz="0.00000073" izz="0.0078035"/>
    </inertial>
    <visual>
      <origin rpy="0 0 0" xyz="0 0 0"/>
      <geometry>
        <mesh filename="package://d1h_description/meshes/L_foot.STL"/>
      </geometry>
      <material name="">
        <color rgba="0.698039215686274 0.698039215686274 0.698039215686274 1"/>
      </material>
    </visual>
    <collision>
      <origin rpy="0 0 0" xyz="0 0 0.0"/>
      <geometry>
        <cylinder length="0.04" radius="0.087"/>
      </geometry>
    </collision>
  </link>
  <joint name="FL_foot_joint" type="revolute">
    <origin rpy="0 0 0" xyz="0.25 0 0.052166"/>
    <parent link="FL_calf"/>
    <child link="FL_foot"/>
    <axis xyz="0 0 1"/>
    <dynamics damping="0.5" friction="0.0"/>
    <limit effort="12" lower="-31415926" upper="31415926" velocity="30.0"/>
  </joint>
  <!-- Right hip link -->
  <link name="FR_hip">
    <inertial>
      <origin rpy="0 0 0" xyz="0.01567834 -0.00005214 -0.09306094"/>
      <mass value="1.86700"/>
      <inertia ixx="0.004561" ixy="0.00000066" ixz="0.00004878" iyy="0.0034067" iyz="-0.00000146" izz="0.0026097"/>
    </inertial>
    <visual>
      <origin rpy="0 0 0" xyz="0 0 0"/>
      <geometry>
        <mesh filename="package://d1h_description/meshes/R_hip.STL"/>
      </geometry>
      <material name="">
        <color rgba="0.75294 0.75294 0.75294 1"/>
      </material>
    </visual>
  </link>
  <joint name="FR_hip_joint" type="revolute">
    <origin rpy="1.5708 0 1.5708" xyz="0.0945 -0.0775 0"/>
    <parent link="F_base_link"/>
    <child link="FR_hip"/>
    <axis xyz="0 0 1"/>
    <dynamics damping="0.2346" friction="0.943"/>
    <limit effort="80" lower="-0.7853981633974483" upper="0.7853981633974483" velocity="20"/>
  </joint>
  <!-- Right thigh link -->
  <link name="FR_thigh">
    <inertial>
      <origin rpy="0 0 0" xyz="0.03137957 0.00371556 -0.06475707"/>
      <mass value="2.81160"/>
      <inertia ixx="0.00486845" ixy="-0.00149037" ixz="0.00234002" iyy="0.02037619" iyz="0.00032032" izz="0.02095416"/>
    </inertial>
    <visual>
      <origin rpy="0 0 0" xyz="0 0 0"/>
      <geometry>
        <mesh filename="package://d1h_description/meshes/R_thigh.STL"/>
      </geometry>
      <material name="">
        <color rgba="0.752941176470588 0.752941176470588 0.752941176470588 1"/>
      </material>
    </visual>
    <collision>
      <origin rpy="0 0 0.2617993877991494" xyz="0.06 0.02 0"/>
      <geometry>
        <box size="0.3 0.09 0.05"/>
      </geometry>
    </collision>
  </link>
  <joint name="FR_thigh_joint" type="revolute">
    <origin rpy="-1.5708 0 -1.5712" xyz="-0.0905 0 -0.0945"/>
    <parent link="FR_hip"/>
    <child link="FR_thigh"/>
    <axis xyz="0 0 1"/>
    <dynamics damping="0.2346" friction="0.943"/>
    <limit effort="80" lower="-1.8325957145940461" upper="3.4033920413889422" velocity="20"/>
  </joint>
  <!-- Right knee link -->
  <link name="FR_calf">
    <inertial>
      <origin rpy="0 0 0" xyz="0.12683435 0.01137538 -0.00486802"/>
      <mass value="0.61004"/>
      <inertia ixx="0.00034764" ixy="0.00045139" ixz="0.00028307" iyy="0.0068336" iyz="-0.00001004" izz="0.00692927"/>
    </inertial>
    <visual>
      <origin rpy="0 0 0" xyz="0 0 0"/>
      <geometry>
        <mesh filename="package://d1h_description/meshes/R_calf.STL"/>
      </geometry>
      <material name="">
        <color rgba="0.752941176470588 0.752941176470588 0.752941176470588 1"/>
      </material>
    </visual>
    <collision>
      <origin rpy="0 0 -0.08" xyz="0.15 0.01 0"/>
      <geometry>
        <box size="0.3 0.04 0.05"/>
      </geometry>
    </collision>
  </link>
  <joint name="FR_calf_joint" type="revolute">
    <origin rpy="0.0 0.0 0.0" xyz="0.25 0 0"/>
    <parent link="FR_thigh"/>
    <child link="FR_calf"/>
    <axis xyz="0 0 1"/>
    <dynamics damping="0.2346" friction="0.943"/>
    <limit effort="80" lower="-2.72" upper="-0.85" velocity="20"/>
  </joint>
  <!-- Right wheel link -->
  <link name="FR_foot">
    <inertial>
      <origin rpy="0 0 0" xyz="0.0000105 0.0000048 -0.02475"/>
      <mass value="1.75470"/>
      <inertia ixx="0.00414978" ixy="-0.00000164" ixz="0.00000051" iyy="0.00414822" iyz="0.00000155" izz="0.0078035"/>
    </inertial>
    <visual>
      <origin rpy="0 0 0" xyz="0 0 0"/>
      <geometry>
        <mesh filename="package://d1h_description/meshes/R_foot.STL"/>
      </geometry>
      <material name="">
        <color rgba="1 1 1 1"/>
      </material>
    </visual>
    <collision>
      <origin rpy="0 0 0" xyz="0 0 -0.0"/>
      <geometry>
        <cylinder length="0.04" radius="0.087"/>
      </geometry>
    </collision>
  </link>
  <joint name="FR_foot_joint" type="revolute">
    <origin rpy="0 0 2.3965" xyz="0.25 0 -0.052166"/>
    <parent link="FR_calf"/>
    <child link="FR_foot"/>
    <axis xyz="0 0 1"/>
    <dynamics damping="0.5" friction="0.0"/>
    <limit effort="12" lower="-31415926" upper="31415926" velocity="30.0"/>
  </joint>
  <!-- Base link -->
  <link name="R_base_link">
    <inertial>
      <origin rpy="0 0 0" xyz="0.03074 0.00016 -0.03314"/>
      <mass value="9.158"/>
      <inertia ixx="0.073416" ixy="0.00014675" ixz="-0.0079314" iyy="0.12672" iyz="1.9414e-05" izz="0.11933"/>
    </inertial>
    <visual>
      <origin rpy="0 0 0" xyz="0 0 0"/>
      <geometry>
        <mesh filename="package://d1h_description/meshes/base_link.STL"/>
      </geometry>
      <material name="">
        <color rgba="0.75294 0.75294 0.75294 1"/>
      </material>
    </visual>
    <collision>
      <origin rpy="0 0 0" xyz="0 0 0"/>
      <geometry>
        <box size="0.275 0.15 0.18"/>
      </geometry>
    </collision>
    <collision>
      <origin rpy="0 0 0" xyz="0 0 -0.12"/>
      <geometry>
        <box size="0.35 0.15 0.1"/>
      </geometry>
    </collision>
  </link>
  <joint name="R_base_joint" type="fixed">
    <origin rpy="0 0 0" xyz="-0.553 0 0"/>
    <parent link="base_link"/>
    <child link="R_base_link"/>
  </joint>
  <!-- Funtion link -->
  <link name="R_funtion_link">
    <inertial>
      <origin rpy="0 0 0" xyz="-0.02031 -0.00001 0.00546"/>
      <mass value="0.7859"/>
      <inertia ixx="0.005595" ixy="0.0" ixz="-4.5e-05" iyy="0.002202" iyz="0.0" izz="0.003725"/>
    </inertial>
    <visual>
      <origin rpy="0 0 0" xyz="0 0 0"/>
      <geometry>
        <mesh filename="package://d1h_description/meshes/funtion_Link.STL"/>
      </geometry>
      <material name="">
        <color rgba="0.75294 0.75294 0.75294 1"/>
      </material>
    </visual>
    <collision>
      <origin rpy="0 0 0" xyz="0.008 0 0"/>
      <geometry>
        <box size="0.0495 0.15 0.18"/>
      </geometry>
    </collision>
  </link>
  <joint name="R_funtion_joint" type="fixed">
    <origin rpy="0 0 3.14159" xyz="-0.1545 0 0"/>
    <parent link="R_base_link"/>
    <child link="R_funtion_link"/>
    <axis xyz="0 0 0"/>
  </joint>
  <!-- Docking link -->
  <link name="R_docking_link">
    <inertial>
      <origin rpy="0 0 0" xyz="0.01167 0.01142 0.00562"/>
      <mass value="1.1043"/>
      <inertia ixx="0.007968" ixy="0.000348" ixz="1.4e-05" iyy="0.002634" iyz="-1.7e-05" izz="0.005995"/>
    </inertial>
    <visual>
      <origin rpy="0 0 0" xyz="0 0 0"/>
      <geometry>
        <mesh filename="package://d1h_description/meshes/docking_Link.STL"/>
      </geometry>
      <material name="">
        <color rgba="0.75294 0.75294 0.75294 1"/>
      </material>
    </visual>
    <collision>
      <origin rpy="0 0 0" xyz="0.0065 0 0"/>
      <geometry>
        <box size="0.0495 0.15 0.175"/>
      </geometry>
    </collision>
  </link>
  <joint name="R_docking_joint" type="fixed">
    <origin rpy="0 0 3.14159" xyz="0.187 0 0"/>
    <parent link="R_base_link"/>
    <child link="R_docking_link"/>
    <axis xyz="0 0 0"/>
  </joint>
  <!-- Left hip link -->
  <link name="RL_hip">
    <inertial>
      <origin rpy="0 0 0" xyz="-0.01567766 -0.00005214 -0.09306106"/>
      <mass value="1.86700"/>
      <inertia ixx="0.004561" ixy="-0.00000066" ixz="-0.00004876" iyy="0.0034067" iyz="-0.00000146" izz="0.0026097"/>
    </inertial>
    <visual>
      <origin rpy="0 0 0" xyz="0 0 0"/>
      <geometry>
        <mesh filename="package://d1h_description/meshes/L_hip.STL"/>
      </geometry>
      <material name="">
        <color rgba="0.75294 0.75294 0.75294 1"/>
      </material>
    </visual>
  </link>
  <joint name="RL_hip_joint" type="revolute">
    <origin rpy="1.5708 0 1.5708" xyz="0.0945 0.0775 0"/>
    <parent link="R_base_link"/>
    <child link="RL_hip"/>
    <axis xyz="0 0 1"/>
    <dynamics damping="0.2346" friction="0.943"/>
    <limit effort="80" lower="-0.7853981633974483" upper="0.7853981633974483" velocity="20"/>
  </joint>
  <!-- Left thigh link -->
  <link name="RL_thigh">
    <inertial>
      <origin rpy="0 0 0" xyz="0.03137855 0.00371524 0.06475758"/>
      <mass value="2.81160"/>
      <inertia ixx="0.00486852" ixy="-0.00149035" ixz="-0.00234028" iyy="0.0203762" iyz="-0.00032034" izz="0.02095408"/>
    </inertial>
    <visual>
      <origin rpy="0 0 0" xyz="0 0 0"/>
      <geometry>
        <mesh filename="package://d1h_description/meshes/L_thigh.STL"/>
      </geometry>
      <material name="">
        <color rgba="0.75294 0.75294 0.75294 1"/>
      </material>
    </visual>
    <collision>
      <origin rpy="0 0 0.2617993877991494" xyz="0.06 0.02 0"/>
      <geometry>
        <box size="0.3 0.09 0.05"/>
      </geometry>
    </collision>
  </link>
  <joint name="RL_thigh_joint" type="revolute">
    <origin rpy="-1.5708 0 -1.5704" xyz="0.0905 0 -0.0945"/>
    <parent link="RL_hip"/>
    <child link="RL_thigh"/>
    <axis xyz="0 0 1"/>
    <dynamics damping="0.2346" friction="0.943"/>
    <limit effort="80" lower="-1.8325957145940461" upper="3.4033920413889422" velocity="20"/>
  </joint>
  <!-- Left knee link -->
  <link name="RL_calf">
    <inertial>
      <origin rpy="0 0 0" xyz="0.12683437 0.01137531 0.00486771"/>
      <mass value="0.61004"/>
      <inertia ixx="0.00034763" ixy="0.00045139" ixz="-0.00028304" iyy="0.0068336" iyz="0.00001004" izz="0.00692927"/>
    </inertial>
    <visual>
      <origin rpy="0 0 0" xyz="0 0 0"/>
      <geometry>
        <mesh filename="package://d1h_description/meshes/L_calf.STL"/>
      </geometry>
      <material name="">
        <color rgba="0.75294 0.75294 0.75294 1"/>
      </material>
    </visual>
    <collision>
      <origin rpy="0 0 -0.08" xyz="0.15 0.01 0"/>
      <geometry>
        <box size="0.3 0.04 0.05"/>
      </geometry>
    </collision>
  </link>
  <joint name="RL_calf_joint" type="revolute">
    <origin rpy="-0.0 0.0 0.0" xyz="0.25 0 0"/>
    <parent link="RL_thigh"/>
    <child link="RL_calf"/>
    <axis xyz="0 0 1"/>
    <dynamics damping="0.2346" friction="0.943"/>
    <limit effort="80" lower="-2.72" upper="-0.85" velocity="20"/>
  </joint>
  <!-- Left wheel link -->
  <link name="RL_foot">
    <inertial>
      <origin rpy="0 0 0" xyz="-0.00001088 0.00000319 0.02475"/>
      <mass value="1.75470"/>
      <inertia ixx="0.00414743" ixy="-0.00000091" ixz="0.00000144" iyy="0.00415057" iyz="0.00000073" izz="0.0078035"/>
    </inertial>
    <visual>
      <origin rpy="0 0 0" xyz="0 0 0"/>
      <geometry>
        <mesh filename="package://d1h_description/meshes/L_foot.STL"/>
      </geometry>
      <material name="">
        <color rgba="0.698039215686274 0.698039215686274 0.698039215686274 1"/>
      </material>
    </visual>
    <collision>
      <origin rpy="0 0 0" xyz="0 0 0.0"/>
      <geometry>
        <cylinder length="0.04" radius="0.087"/>
      </geometry>
    </collision>
  </link>
  <joint name="RL_foot_joint" type="revolute">
    <origin rpy="0 0 0" xyz="0.25 0 0.052166"/>
    <parent link="RL_calf"/>
    <child link="RL_foot"/>
    <axis xyz="0 0 1"/>
    <dynamics damping="0.5" friction="0.0"/>
    <limit effort="12" lower="-31415926" upper="31415926" velocity="30.0"/>
  </joint>
  <!-- Right hip link -->
  <link name="RR_hip">
    <inertial>
      <origin rpy="0 0 0" xyz="0.01567834 -0.00005214 -0.09306094"/>
      <mass value="1.86700"/>
      <inertia ixx="0.004561" ixy="0.00000066" ixz="0.00004878" iyy="0.0034067" iyz="-0.00000146" izz="0.0026097"/>
    </inertial>
    <visual>
      <origin rpy="0 0 0" xyz="0 0 0"/>
      <geometry>
        <mesh filename="package://d1h_description/meshes/R_hip.STL"/>
      </geometry>
      <material name="">
        <color rgba="0.75294 0.75294 0.75294 1"/>
      </material>
    </visual>
  </link>
  <joint name="RR_hip_joint" type="revolute">
    <origin rpy="1.5708 0 1.5708" xyz="0.0945 -0.0775 0"/>
    <parent link="R_base_link"/>
    <child link="RR_hip"/>
    <axis xyz="0 0 1"/>
    <dynamics damping="0.2346" friction="0.943"/>
    <limit effort="80" lower="-0.7853981633974483" upper="0.7853981633974483" velocity="20"/>
  </joint>
  <!-- Right thigh link -->
  <link name="RR_thigh">
    <inertial>
      <origin rpy="0 0 0" xyz="0.03137957 0.00371556 -0.06475707"/>
      <mass value="2.81160"/>
      <inertia ixx="0.00486845" ixy="-0.00149037" ixz="0.00234002" iyy="0.02037619" iyz="0.00032032" izz="0.02095416"/>
    </inertial>
    <visual>
      <origin rpy="0 0 0" xyz="0 0 0"/>
      <geometry>
        <mesh filename="package://d1h_description/meshes/R_thigh.STL"/>
      </geometry>
      <material name="">
        <color rgba="0.752941176470588 0.752941176470588 0.752941176470588 1"/>
      </material>
    </visual>
    <collision>
      <origin rpy="0 0 0.2617993877991494" xyz="0.06 0.02 0"/>
      <geometry>
        <box size="0.3 0.09 0.05"/>
      </geometry>
    </collision>
  </link>
  <joint name="RR_thigh_joint" type="revolute">
    <origin rpy="-1.5708 0 -1.5712" xyz="-0.0905 0 -0.0945"/>
    <parent link="RR_hip"/>
    <child link="RR_thigh"/>
    <axis xyz="0 0 1"/>
    <dynamics damping="0.2346" friction="0.943"/>
    <limit effort="80" lower="-1.8325957145940461" upper="3.4033920413889422" velocity="20"/>
  </joint>
  <!-- Right knee link -->
  <link name="RR_calf">
    <inertial>
      <origin rpy="0 0 0" xyz="0.12683435 0.01137538 -0.00486802"/>
      <mass value="0.61004"/>
      <inertia ixx="0.00034764" ixy="0.00045139" ixz="0.00028307" iyy="0.0068336" iyz="-0.00001004" izz="0.00692927"/>
    </inertial>
    <visual>
      <origin rpy="0 0 0" xyz="0 0 0"/>
      <geometry>
        <mesh filename="package://d1h_description/meshes/R_calf.STL"/>
      </geometry>
      <material name="">
        <color rgba="0.752941176470588 0.752941176470588 0.752941176470588 1"/>
      </material>
    </visual>
    <collision>
      <origin rpy="0 0 -0.08" xyz="0.15 0.01 0"/>
      <geometry>
        <box size="0.3 0.04 0.05"/>
      </geometry>
    </collision>
  </link>
  <joint name="RR_calf_joint" type="revolute">
    <origin rpy="0.0 0.0 0.0" xyz="0.25 0 0"/>
    <parent link="RR_thigh"/>
    <child link="RR_calf"/>
    <axis xyz="0 0 1"/>
    <dynamics damping="0.2346" friction="0.943"/>
    <limit effort="80" lower="-2.72" upper="-0.85" velocity="20"/>
  </joint>
  <!-- Right wheel link -->
  <link name="RR_foot">
    <inertial>
      <origin rpy="0 0 0" xyz="0.0000105 0.0000048 -0.02475"/>
      <mass value="1.75470"/>
      <inertia ixx="0.00414978" ixy="-0.00000164" ixz="0.00000051" iyy="0.00414822" iyz="0.00000155" izz="0.0078035"/>
    </inertial>
    <visual>
      <origin rpy="0 0 0" xyz="0 0 0"/>
      <geometry>
        <mesh filename="package://d1h_description/meshes/R_foot.STL"/>
      </geometry>
      <material name="">
        <color rgba="1 1 1 1"/>
      </material>
    </visual>
    <collision>
      <origin rpy="0 0 0" xyz="0 0 -0.0"/>
      <geometry>
        <cylinder length="0.04" radius="0.087"/>
      </geometry>
    </collision>
  </link>
  <joint name="RR_foot_joint" type="revolute">
    <origin rpy="0 0 2.3965" xyz="0.25 0 -0.052166"/>
    <parent link="RR_calf"/>
    <child link="RR_foot"/>
    <axis xyz="0 0 1"/>
    <dynamics damping="0.5" friction="0.0"/>
    <limit effort="12" lower="-31415926" upper="31415926" velocity="30.0"/>
  </joint>
</robot>
